Workbook

Sheet aderyn_impact_outreach_dataset
A1: Participant_ID | B1: Age | C1: Age_Group | D1: Gender | E1: Community_Role | F1: Language_Spoken | G1: English_Proficiency | H1: Participant_Type | I1: Heard_About_Outreach | J1: Information_Source | K1: Attendance_Status | L1: Arrival_Time | M1: Sessions_Attended | N1: Programme_Understanding | O1: Perceived_Purpose | P1: Trust_Level | Q1: Comfort_Level | R1: Participation_Level | S1: Feedback_Provided | T1: Satisfaction_Score | U1: Main_Concern | V1: Preferred_Communication_Method | W1: Would_Attend_Follow_Up | X1: Follow_Up_Preference | Y1: Key_Feedback
A2: AII-001 | B2: 15 | C2: 13â€“19 | D2: Female | E2: Community member | F2: Adara | G2: Basic | H2: Girl | I2: Yes | J2: Village/community leader | K2: Attended | L2: More than 30 minutes late | M2: 3 | N2: Clear | O2: Women health, education and support services | P2: Very high | Q2: Very comfortable | R2: Contributed to discussion | S2: Yes | T2: 5 | U2: Need for elder engagement | V2: Local-language community meeting | W2: Yes | X2: Local-language community meeting | Y2: Meet village elders and gatekeepers before inviting participants.
A3: AII-002 | B3: 40 | C3: 40â€“49 | D3: Female | E3: Village/community leader | F3: English | G3: Conversational | H3: Adult woman | I3: Yes | J3: Family member | K3: Attended | L3: On time | M3: 4 | N3: Clear | O3: Women health, education and support services | P3: Low | Q3: Neutral | R3: Asked one question | S3: Yes | T3: 2 | U3: Need for elder engagement | V3: Local-language community meeting | W3: Yes | X3: Local-language community meeting | Y3: Meet village elders and gatekeepers before inviting participants.
A4: AII-003 | B4: 16 | C4: 13â€“19 | D4: Female | E4: Adolescent participant | F4: Gbagyi | G4: Conversational | H4: Girl | I4: Yes | J4: Teacher/school contact | K4: Attended | L4: On time | M4: 4 | N4: Clear | O4: Women health, education and support services | P4: High | Q4: Comfortable | R4: Contributed to discussion | S4: Yes | T4: 4 | U4: Need for clearer purpose explanation | V4: Local-language community meeting | W4: Yes | X4: Local-language community meeting | Y4: State clearly that the outreach is for health, education and referral information.
A5: AII-004 | B5: 51 | C5: 50+ | D5: Female | E5: Community member | F5: Adara | G5: Conversational | H5: Adult woman | I5: Yes | J5: Teacher/school contact | K5: Attended | L5: On time | M5: 5 | N5: Clear | O5: Women health, education and support services | P5: Moderate | Q5: Uncomfortable | R5: Asked one question | S5: Yes | T5: 3 | U5: Need for clearer purpose explanation | V5: Local-language community meeting | W5: Yes | X5: Local-language community meeting | Y5: State clearly that the outreach is for health, education and referral information.
A6: AII-005 | B6: 35 | C6: 30â€“39 | D6: Female | E6: Village/community leader | F6: Hausa | G6: Conversational | H6: Adult woman | I6: Yes | J6: Religious/community announcement | K6: Attended | L6: On time | M6: 4 | N6: Clear | O6: Women health, education and support services | P6: Very high | Q6: Very comfortable | R6: Actively engaged | S6: Yes | T6: 5 | U6: Need for elder engagement | V6: Local-language community meeting | W6: Yes | X6: Local-language community meeting | Y6: Meet village elders and gatekeepers before inviting participants.
A7: AII-006 | B7: 44 | C7: 40â€“49 | D7: Female | E7: Community member | F7: English | G7: Fluent | H7: Adult woman | I7: Yes | J7: Women group representative | K7: Attended | L7: On time | M7: 3 | N7: Clear | O7: Women health, education and support services | P7: Moderate | Q7: Neutral | R7: Asked one question | S7: No | T7: 3 | U7: Need for clearer purpose explanation | V7: Local-language community meeting | W7: Maybe | X7: Local-language community meeting | Y7: No feedback recorded.
A8: AII-007 | B8: 48 | C8: 40â€“49 | D8: Female | E8: Parent/guardian | F8: Adara | G8: Basic | H8: Adult woman | I8: Yes | J8: Field team invitation | K8: Did not attend | L8: Did not attend | M8: 0 | N8: Not assessed | O8: Not assessed | P8: Not assessed | Q8: Not assessed | R8: Not assessed | S8: No | T8: Not rated | U8: Concern about programme purpose | V8: Women group meeting | W8: Yes | X8: Women group meeting | Y8: Explain the purpose clearly to community leaders first.
A9: AII-008 | B9: 41 | C9: 40â€“49 | D9: Female | E9: Community member | F9: Hausa | G9: None | H9: Adult woman | I9: Yes | J9: Village/community leader | K9: Attended | L9: On time | M9: 4 | N9: Partial | O9: Unclear; possibly external influence | P9: Moderate | Q9: Neutral | R9: Asked one question | S9: No | T9: 3 | U9: Language barrier | V9: Women group meeting | W9: No | X9: Women group meeting | Y9: No feedback recorded.
A10: AII-009 | B10: 37 | C10: 30â€“39 | D10: Female | E10: Community member | F10: Adara | G10: None | H10: Adult woman | I10: Yes | J10: Friend/neighbour | K10: Attended | L10: On time | M10: 4 | N10: Limited | O10: Unclear; possibly external influence | P10: Low | Q10: Very uncomfortable | R10: Asked one question | S10: No | T10: 1 | U10: Language barrier | V10: Women group meeting | W10: Maybe | X10: Women group meeting | Y10: No feedback recorded.
A11: AII-010 | B11: 31 | C11: 30â€“39 | D11: Female | E11: Parent/guardian | F11: Hausa | G11: Basic | H11: Adult woman | I11: No | J11: Not applicable | K11: Did not attend | L11: Did not attend | M11: 0 | N11: Not assessed | O11: Not assessed | P11: Not assessed | Q11: Not assessed | R11: Not assessed | S11: No | T11: Not rated | U11: Did not hear about programme | V11: School-based session | W11: No | X11: School-based session | Y11: Use community announcements and local networks earlier.
A12: AII-011 | B12: 13 | C12: 13â€“19 | D12: Female | E12: Adolescent participant | F12: Hausa | G12: Conversational | H12: Girl | I12: Yes | J12: Family member | K12: Attended | L12: More than 30 minutes late | M12: 2 | N12: Clear | O12: Women health, education and support services | P12: Low | Q12: Neutral | R12: Observed only | S12: No | T12: 2 | U12: Need for elder engagement | V12: School-based session | W12: Maybe | X12: School-based session | Y12: No feedback recorded.
A13: AII-012 | B13: 45 | C13: 40â€“49 | D13: Female | E13: Community member | F13: Adara | G13: None | H13: Adult woman | I13: Yes | J13: Teacher/school contact | K13: Attended | L13: 15â€“30 minutes late | M13: 5 | N13: Partial | O13: Women health and education | P13: Moderate | Q13: Comfortable | R13: Contributed to discussion | S13: No | T13: 5 | U13: Language barrier | V13: School-based session | W13: Maybe | X13: School-based session | Y13: No feedback recorded.
A14: AII-013 | B14: 21 | C14: 20â€“29 | D14: Female | E14: Community member | F14: English | G14: Fluent | H14: Young woman | I14: Yes | J14: Friend/neighbour | K14: Attended | L14: 15â€“30 minutes late | M14: 4 | N14: Clear | O14: Women health, education and support services | P14: High | Q14: Comfortable | R14: Asked one question | S14: Yes | T14: 4 | U14: Language barrier | V14: School-based session | W14: Yes | X14: School-based session | Y14: Use an Adara/Hausa interpreter and explain each topic slowly.
A15: AII-014 | B15: 19 | C15: 13â€“19 | D15: Female | E15: Community member | F15: Adara | G15: None | H15: Young woman | I15: Yes | J15: Village/community leader | K15: Did not attend | L15: Did not attend | M15: 0 | N15: Not assessed | O15: Not assessed | P15: Not assessed | Q15: Not assessed | R15: Not assessed | S15: No | T15: Not rated | U15: Household/time constraints | V15: Local-language community meeting | W15: Yes | X15: Local-language community meeting | Y15: Choose a time that does not conflict with household responsibilities.
A16: AII-015 | B16: 24 | C16: 20â€“29 | D16: Female | E16: Parent/guardian | F16: English | G16: Fluent | H16: Young woman | I16: Yes | J16: Village/community leader | K16: Attended | L16: On time | M16: 5 | N16: Clear | O16: Women health, education and support services | P16: Very high | Q16: Comfortable | R16: Asked one question | S16: Yes | T16: 5 | U16: Need for clearer purpose explanation | V16: School-based session | W16: Yes | X16: School-based session | Y16: State clearly that the outreach is for health, education and referral information.
A17: AII-016 | B17: 37 | C17: 30â€“39 | D17: Female | E17: Parent/guardian | F17: Adara | G17: None | H17: Adult woman | I17: Yes | J17: Family member | K17: Did not attend | L17: Did not attend | M17: 0 | N17: Not assessed | O17: Not assessed | P17: Not assessed | Q17: Not assessed | R17: Not assessed | S17: No | T17: Not rated | U17: Concern about programme purpose | V17: Home/compound visit | W17: Yes | X17: Home/compound visit | Y17: Explain the purpose clearly to community leaders first.
A18: AII-017 | B18: 53 | C18: 50+ | D18: Female | E18: Parent/guardian | F18: English | G18: Conversational | H18: Adult woman | I18: Yes | J18: Teacher/school contact | K18: Attended | L18: On time | M18: 4 | N18: Clear | O18: Women health, education and support services | P18: Moderate | Q18: Neutral | R18: Listened quietly | S18: No | T18: 3 | U18: Language barrier | V18: School-based session | W18: Yes | X18: School-based session | Y18: No feedback recorded.
A19: AII-018 | B19: 36 | C19: 30â€“39 | D19: Female | E19: Teacher | F19: Gbagyi | G19: Basic | H19: Community stakeholder | I19: Yes | J19: Field team invitation | K19: Did not attend | L19: Did not attend | M19: 0 | N19: Not assessed | O19: Not assessed | P19: Not assessed | Q19: Not assessed | R19: Not assessed | S19: No | T19: Not rated | U19: Concern about programme purpose | V19: School-based session | W19: Yes | X19: School-based session | Y19: Explain the purpose clearly to community leaders first.
A20: AII-019 | B20: 31 | C20: 30â€“39 | D20: Female | E20: Teacher | F20: English | G20: Fluent | H20: Adult woman | I20: Yes | J20: Field team invitation | K20: Attended | L20: 15â€“30 minutes late | M20: 3 | N20: Clear | O20: Women health, education and support services | P20: Moderate | Q20: Uncomfortable | R20: Listened quietly | S20: Yes | T20: 2 | U20: No major concern | V20: School-based session | W20: Yes | X20: School-based session | Y20: The team was respectful; repeat the session with local support.
A21: AII-020 | B21: 30 | C21: 30â€“39 | D21: Female | E21: Teacher | F21: Adara | G21: Conversational | H21: Adult woman | I21: Yes | J21: Friend/neighbour | K21: Did not attend | L21: Did not attend | M21: 0 | N21: Not assessed | O21: Not assessed | P21: Not assessed | Q21: Not assessed | R21: Not assessed | S21: No | T21: Not rated | U21: Language barrier | V21: Home/compound visit | W21: No | X21: Home/compound visit | Y21: Use a trusted local-language interpreter.
A22: AII-021 | B22: 13 | C22: 13â€“19 | D22: Female | E22: Community member | F22: Adara | G22: None | H22: Girl | I22: Yes | J22: Friend/neighbour | K22: Attended | L22: 15â€“30 minutes late | M22: 3 | N22: Limited | O22: Health talk only | P22: Very low | Q22: Uncomfortable | R22: Listened quietly | S22: Yes | T22: 2 | U22: No major concern | V22: Women group meeting | W22: Maybe | X22: Women group meeting | Y22: The team was respectful; repeat the session with local support.
A23: AII-022 | B23: 19 | C23: 13â€“19 | D23: Female | E23: Adolescent participant | F23: Adara | G23: Basic | H23: Young woman | I23: No | J23: Not applicable | K23: Did not attend | L23: Did not attend | M23: 0 | N23: Not assessed | O23: Not assessed | P23: Not assessed | Q23: Not assessed | R23: Not assessed | S23: No | T23: Not rated | U23: Did not hear about programme | V23: Women group meeting | W23: Maybe | X23: Women group meeting | Y23: Use community announcements and local networks earlier.
A24: AII-023 | B24: 56 | C24: 50+ | D24: Female | E24: Community member | F24: English | G24: Basic | H24: Adult woman | I24: Yes | J24: Teacher/school contact | K24: Attended | L24: 15â€“30 minutes late | M24: 5 | N24: Partial | O24: Women health and education | P24: Moderate | Q24: Neutral | R24: Contributed to discussion | S24: Yes | T24: 4 | U24: Need for elder engagement | V24: Local-language community meeting | W24: No | X24: Local-language community meeting | Y24: Meet village elders and gatekeepers before inviting participants.
A25: AII-024 | B25: 41 | C25: 40â€“49 | D25: Female | E25: Community member | F25: English | G25: Basic | H25: Adult woman | I25: Yes | J25: Teacher/school contact | K25: Did not attend | L25: Did not attend | M25: 0 | N25: Not assessed | O25: Not assessed | P25: Not assessed | Q25: Not assessed | R25: Not assessed | S25: No | T25: Not rated | U25: Language barrier | V25: School-based session | W25: Maybe | X25: School-based session | Y25: Use a trusted local-language interpreter.
A26: AII-025 | B26: 28 | C26: 20â€“29 | D26: Female | E26: Community member | F26: Adara | G26: None | H26: Young woman | I26: Yes | J26: Women group representative | K26: Did not attend | L26: Did not attend | M26: 0 | N26: Not assessed | O26: Not assessed | P26: Not assessed | Q26: Not assessed | R26: Not assessed | S26: No | T26: Not rated | U26: Household/time constraints | V26: Radio announcement | W26: Yes | X26: Radio announcement | Y26: Choose a time that does not conflict with household responsibilities.
A27: AII-026 | B27: 18 | C27: 13â€“19 | D27: Female | E27: Adolescent participant | F27: Adara | G27: None | H27: Young woman | I27: Yes | J27: Village/community leader | K27: Did not attend | L27: Did not attend | M27: 0 | N27: Not assessed | O27: Not assessed | P27: Not assessed | Q27: Not assessed | R27: Not assessed | S27: No | T27: Not rated | U27: Concern about programme purpose | V27: Women group meeting | W27: Maybe | X27: Women group meeting | Y27: Explain the purpose clearly to community leaders first.
A28: AII-027 | B28: 14 | C28: 13â€“19 | D28: Female | E28: Community member | F28: Adara | G28: None | H28: Girl | I28: Yes | J28: Field team invitation | K28: Attended | L28: On time | M28: 1 | N28: Limited | O28: Unclear; possibly external influence | P28: Very low | Q28: Very uncomfortable | R28: Observed only | S28: Yes | T28: 1 | U28: Household/time constraints | V28: Women group meeting | W28: No | X28: Women group meeting | Y28: Hold the next meeting after household chores and give advance notice.
A29: AII-028 | B29: 29 | C29: 20â€“29 | D29: Female | E29: Community member | F29: Adara | G29: Basic | H29: Young woman | I29: Yes | J29: Friend/neighbour | K29: Attended | L29: On time | M29: 2 | N29: Partial | O29: Women health and education | P29: Low | Q29: Very uncomfortable | R29: Observed only | S29: Yes | T29: 1 | U29: No major concern | V29: Women group meeting | W29: No | X29: Women group meeting | Y29: The team was respectful; repeat the session with local support.
A30: AII-029 | B30: 15 | C30: 13â€“19 | D30: Female | E30: Adolescent participant | F30: Adara | G30: Conversational | H30: Girl | I30: Yes | J30: Village/community leader | K30: Attended | L30: 15â€“30 minutes late | M30: 5 | N30: Clear | O30: Women health, education and support services | P30: High | Q30: Comfortable | R30: Asked one question | S30: Yes | T30: 4 | U30: Need for clearer purpose explanation | V30: Women group meeting | W30: Yes | X30: Women group meeting | Y30: State clearly that the outreach is for health, education and referral information.
A31: AII-030 | B31: 15 | C31: 13â€“19 | D31: Female | E31: Adolescent participant | F31: Adara | G31: None | H31: Girl | I31: Yes | J31: Family member | K31: Attended | L31: 15â€“30 minutes late | M31: 2 | N31: Partial | O31: Unclear; possibly external influence | P31: Low | Q31: Neutral | R31: Listened quietly | S31: Yes | T31: 2 | U31: Need for clearer purpose explanation | V31: Women group meeting | W31: Maybe | X31: Women group meeting | Y31: State clearly that the outreach is for health, education and referral information.
A32: AII-031 | B32: 36 | C32: 30â€“39 | D32: Female | E32: Community member | F32: Adara | G32: None | H32: Adult woman | I32: Yes | J32: Friend/neighbour | K32: Did not attend | L32: Did not attend | M32: 0 | N32: Not assessed | O32: Not assessed | P32: Not assessed | Q32: Not assessed | R32: Not assessed | S32: No | T32: Not rated | U32: Concern about programme purpose | V32: Home/compound visit | W32: Yes | X32: Home/compound visit | Y32: Explain the purpose clearly to community leaders first.
A33: AII-032 | B33: 14 | C33: 13â€“19 | D33: Female | E33: Community member | F33: Adara | G33: None | H33: Girl | I33: Yes | J33: Friend/neighbour | K33: Attended | L33: On time | M33: 3 | N33: Limited | O33: Unclear; possibly external influence | P33: Very low | Q33: Very uncomfortable | R33: Listened quietly | S33: Yes | T33: 2 | U33: Need for elder engagement | V33: Local-language community meeting | W33: No | X33: Local-language community meeting | Y33: Meet village elders and gatekeepers before inviting participants.
A34: AII-033 | B34: 14 | C34: 13â€“19 | D34: Female | E34: Adolescent participant | F34: Hausa | G34: None | H34: Girl | I34: Yes | J34: Religious/community announcement | K34: Attended | L34: On time | M34: 2 | N34: Limited | O34: Unsure why women and girls were invited | P34: Very low | Q34: Very uncomfortable | R34: Observed only | S34: Yes | T34: 2 | U34: Need for clearer purpose explanation | V34: School-based session | W34: No | X34: School-based session | Y34: State clearly that the outreach is for health, education and referral information.
A35: AII-034 | B35: 46 | C35: 40â€“49 | D35: Female | E35: Parent/guardian | F35: Gbagyi | G35: None | H35: Adult woman | I35: Yes | J35: Women group representative | K35: Attended | L35: 15â€“30 minutes late | M35: 4 | N35: Partial | O35: Unclear; possibly external influence | P35: Moderate | Q35: Neutral | R35: Contributed to discussion | S35: No | T35: 3 | U35: Need for clearer purpose explanation | V35: Women group meeting | W35: No | X35: Women group meeting | Y35: No feedback recorded.
A36: AII-035 | B36: 39 | C36: 30â€“39 | D36: Female | E36: Community member | F36: Adara | G36: Basic | H36: Adult woman | I36: Yes | J36: Women group representative | K36: Attended | L36: 15â€“30 minutes late | M36: 2 | N36: Partial | O36: Women health and education | P36: Moderate | Q36: Neutral | R36: Listened quietly | S36: Yes | T36: 3 | U36: Household/time constraints | V36: Women group meeting | W36: No | X36: Women group meeting | Y36: Hold the next meeting after household chores and give advance notice.
A37: AII-036 | B37: 41 | C37: 40â€“49 | D37: Female | E37: Teacher | F37: Gbagyi | G37: Basic | H37: Adult woman | I37: No | J37: Not applicable | K37: Did not attend | L37: Did not attend | M37: 0 | N37: Not assessed | O37: Not assessed | P37: Not assessed | Q37: Not assessed | R37: Not assessed | S37: No | T37: Not rated | U37: Did not hear about programme | V37: School-based session | W37: No | X37: School-based session | Y37: Use community announcements and local networks earlier.
A38: AII-037 | B38: 61 | C38: 50+ | D38: Female | E38: Village/community leader | F38: Hausa | G38: Basic | H38: Adult woman | I38: Yes | J38: Religious/community announcement | K38: Did not attend | L38: Did not attend | M38: 0 | N38: Not assessed | O38: Not assessed | P38: Not assessed | Q38: Not assessed | R38: Not assessed | S38: No | T38: Not rated | U38: Insufficient prior information | V38: Women group meeting | W38: Maybe | X38: Women group meeting | Y38: Share information through elders and women leaders before the event.
A39: AII-038 | B39: 20 | C39: 20â€“29 | D39: Female | E39: Community member | F39: Adara | G39: Basic | H39: Young woman | I39: Yes | J39: Friend/neighbour | K39: Attended | L39: 15â€“30 minutes late | M39: 2 | N39: Partial | O39: Unclear; possibly external influence | P39: Low | Q39: Uncomfortable | R39: Observed only | S39: No | T39: 3 | U39: Language barrier | V39: Women group meeting | W39: No | X39: Women group meeting | Y39: No feedback recorded.
A40: AII-039 | B40: 15 | C40: 13â€“19 | D40: Female | E40: Adolescent participant | F40: Adara | G40: None | H40: Girl | I40: Yes | J40: Family member | K40: Attended | L40: On time | M40: 3 | N40: Limited | O40: Health talk only | P40: Very low | Q40: Very uncomfortable | R40: Listened quietly | S40: Yes | T40: 2 | U40: No major concern | V40: School-based session | W40: No | X40: School-based session | Y40: The team was respectful; repeat the session with local support.
...

Sheet Clean Data
A1: Participant_ID | B1: Age | C1: Age_Group | D1: Gender | E1: Community_Role | F1: Language_Spoken | G1: English_Proficiency | H1: Participant_Type | I1: Heard_About_Outreach | J1: Information_Source | K1: Attendance_Status | L1: Arrival_Time | M1: Sessions_Attended | N1: Programme_Understanding | O1: Perceived_Purpose | P1: Trust_Level | Q1: Comfort_Level | R1: Participation_Level | S1: Feedback_Provided | T1: Satisfaction_Score | U1: Main_Concern | V1: Preferred_Communication_Method | W1: Would_Attend_Follow_Up | X1: Follow_Up_Preference | Y1: Key_Feedback
A2: AII-001 | B2: 15 | C2: 13 - 19 | D2: Female | E2: Community member | F2: Adara | G2: Basic | H2: Girl | I2: Yes | J2: Village/community leader | K2: Attended | L2: More than 30 minutes late | M2: 3 | N2: Clear | O2: Women health, education and support services | P2: Very high | Q2: Very comfortable | R2: Contributed to discussion | S2: Yes | T2: 5 | U2: Need for elder engagement | V2: Local-language community meeting | W2: Yes | X2: Local-language community meeting | Y2: Meet village elders and gatekeepers before inviting participants.
A3: AII-002 | B3: 40 | C3: 40 - 49 | D3: Female | E3: Village/community leader | F3: English | G3: Conversational | H3: Adult woman | I3: Yes | J3: Family member | K3: Attended | L3: On time | M3: 4 | N3: Clear | O3: Women health, education and support services | P3: Low | Q3: Neutral | R3: Asked one question | S3: Yes | T3: 2 | U3: Need for elder engagement | V3: Local-language community meeting | W3: Yes | X3: Local-language community meeting | Y3: Meet village elders and gatekeepers before inviting participants.
A4: AII-003 | B4: 16 | C4: 13 - 19 | D4: Female | E4: Adolescent participant | F4: Gbagyi | G4: Conversational | H4: Girl | I4: Yes | J4: Teacher/school contact | K4: Attended | L4: On time | M4: 4 | N4: Clear | O4: Women health, education and support services | P4: High | Q4: Comfortable | R4: Contributed to discussion | S4: Yes | T4: 4 | U4: Need for clearer purpose explanation | V4: Local-language community meeting | W4: Yes | X4: Local-language community meeting | Y4: State clearly that the outreach is for health, education and referral information.
A5: AII-004 | B5: 51 | C5: 50+ | D5: Female | E5: Community member | F5: Adara | G5: Conversational | H5: Adult woman | I5: Yes | J5: Teacher/school contact | K5: Attended | L5: On time | M5: 5 | N5: Clear | O5: Women health, education and support services | P5: Moderate | Q5: Uncomfortable | R5: Asked one question | S5: Yes | T5: 3 | U5: Need for clearer purpose explanation | V5: Local-language community meeting | W5: Yes | X5: Local-language community meeting | Y5: State clearly that the outreach is for health, education and referral information.
A6: AII-005 | B6: 35 | C6: 30 - 39 | D6: Female | E6: Village/community leader | F6: Hausa | G6: Conversational | H6: Adult woman | I6: Yes | J6: Religious/community announcement | K6: Attended | L6: On time | M6: 4 | N6: Clear | O6: Women health, education and support services | P6: Very high | Q6: Very comfortable | R6: Actively engaged | S6: Yes | T6: 5 | U6: Need for elder engagement | V6: Local-language community meeting | W6: Yes | X6: Local-language community meeting | Y6: Meet village elders and gatekeepers before inviting participants.
A7: AII-006 | B7: 44 | C7: 40 - 49 | D7: Female | E7: Community member | F7: English | G7: Fluent | H7: Adult woman | I7: Yes | J7: Women group representative | K7: Attended | L7: On time | M7: 3 | N7: Clear | O7: Women health, education and support services | P7: Moderate | Q7: Neutral | R7: Asked one question | S7: No | T7: 3 | U7: Need for clearer purpose explanation | V7: Local-language community meeting | W7: Maybe | X7: Local-language community meeting | Y7: No feedback recorded.
A8: AII-007 | B8: 48 | C8: 40 - 49 | D8: Female | E8: Parent/guardian | F8: Adara | G8: Basic | H8: Adult woman | I8: Yes | J8: Field team invitation | K8: Did not attend | L8: Did not attend | M8: 0 | N8: Not assessed | O8: Not assessed | P8: Not assessed | Q8: Not assessed | R8: Not assessed | S8: No | T8: Not rated | U8: Concern about programme purpose | V8: Women group meeting | W8: Yes | X8: Women group meeting | Y8: Explain the purpose clearly to community leaders first.
A9: AII-008 | B9: 41 | C9: 40 - 49 | D9: Female | E9: Community member | F9: Hausa | G9: None | H9: Adult woman | I9: Yes | J9: Village/community leader | K9: Attended | L9: On time | M9: 4 | N9: Partial | O9: Unclear; possibly external influence | P9: Moderate | Q9: Neutral | R9: Asked one question | S9: No | T9: 3 | U9: Language barrier | V9: Women group meeting | W9: No | X9: Women group meeting | Y9: No feedback recorded.
A10: AII-009 | B10: 37 | C10: 30 - 39 | D10: Female | E10: Community member | F10: Adara | G10: None | H10: Adult woman | I10: Yes | J10: Friend/neighbour | K10: Attended | L10: On time | M10: 4 | N10: Limited | O10: Unclear; possibly external influence | P10: Low | Q10: Very uncomfortable | R10: Asked one question | S10: No | T10: 1 | U10: Language barrier | V10: Women group meeting | W10: Maybe | X10: Women group meeting | Y10: No feedback recorded.
A11: AII-010 | B11: 31 | C11: 30 - 39 | D11: Female | E11: Parent/guardian | F11: Hausa | G11: Basic | H11: Adult woman | I11: No | J11: Not applicable | K11: Did not attend | L11: Did not attend | M11: 0 | N11: Not assessed | O11: Not assessed | P11: Not assessed | Q11: Not assessed | R11: Not assessed | S11: No | T11: Not rated | U11: Did not hear about programme | V11: School-based session | W11: No | X11: School-based session | Y11: Use community announcements and local networks earlier.
A12: AII-011 | B12: 13 | C12: 13 - 19 | D12: Female | E12: Adolescent participant | F12: Hausa | G12: Conversational | H12: Girl | I12: Yes | J12: Family member | K12: Attended | L12: More than 30 minutes late | M12: 2 | N12: Clear | O12: Women health, education and support services | P12: Low | Q12: Neutral | R12: Observed only | S12: No | T12: 2 | U12: Need for elder engagement | V12: School-based session | W12: Maybe | X12: School-based session | Y12: No feedback recorded.
A13: AII-012 | B13: 45 | C13: 40 - 49 | D13: Female | E13: Community member | F13: Adara | G13: None | H13: Adult woman | I13: Yes | J13: Teacher/school contact | K13: Attended | L13: 15 - 30 minutes late | M13: 5 | N13: Partial | O13: Women health and education | P13: Moderate | Q13: Comfortable | R13: Contributed to discussion | S13: No | T13: 5 | U13: Language barrier | V13: School-based session | W13: Maybe | X13: School-based session | Y13: No feedback recorded.
A14: AII-013 | B14: 21 | C14: 20 - 29 | D14: Female | E14: Community member | F14: English | G14: Fluent | H14: Young woman | I14: Yes | J14: Friend/neighbour | K14: Attended | L14: 15 - 30 minutes late | M14: 4 | N14: Clear | O14: Women health, education and support services | P14: High | Q14: Comfortable | R14: Asked one question | S14: Yes | T14: 4 | U14: Language barrier | V14: School-based session | W14: Yes | X14: School-based session | Y14: Use an Adara/Hausa interpreter and explain each topic slowly.
A15: AII-014 | B15: 19 | C15: 13 - 19 | D15: Female | E15: Community member | F15: Adara | G15: None | H15: Young woman | I15: Yes | J15: Village/community leader | K15: Did not attend | L15: Did not attend | M15: 0 | N15: Not assessed | O15: Not assessed | P15: Not assessed | Q15: Not assessed | R15: Not assessed | S15: No | T15: Not rated | U15: Household/time constraints | V15: Local-language community meeting | W15: Yes | X15: Local-language community meeting | Y15: Choose a time that does not conflict with household responsibilities.
A16: AII-015 | B16: 24 | C16: 20 - 29 | D16: Female | E16: Parent/guardian | F16: English | G16: Fluent | H16: Young woman | I16: Yes | J16: Village/community leader | K16: Attended | L16: On time | M16: 5 | N16: Clear | O16: Women health, education and support services | P16: Very high | Q16: Comfortable | R16: Asked one question | S16: Yes | T16: 5 | U16: Need for clearer purpose explanation | V16: School-based session | W16: Yes | X16: School-based session | Y16: State clearly that the outreach is for health, education and referral information.
A17: AII-016 | B17: 37 | C17: 30 - 39 | D17: Female | E17: Parent/guardian | F17: Adara | G17: None | H17: Adult woman | I17: Yes | J17: Family member | K17: Did not attend | L17: Did not attend | M17: 0 | N17: Not assessed | O17: Not assessed | P17: Not assessed | Q17: Not assessed | R17: Not assessed | S17: No | T17: Not rated | U17: Concern about programme purpose | V17: Home/compound visit | W17: Yes | X17: Home/compound visit | Y17: Explain the purpose clearly to community leaders first.
A18: AII-017 | B18: 53 | C18: 50+ | D18: Female | E18: Parent/guardian | F18: English | G18: Conversational | H18: Adult woman | I18: Yes | J18: Teacher/school contact | K18: Attended | L18: On time | M18: 4 | N18: Clear | O18: Women health, education and support services | P18: Moderate | Q18: Neutral | R18: Listened quietly | S18: No | T18: 3 | U18: Language barrier | V18: School-based session | W18: Yes | X18: School-based session | Y18: No feedback recorded.
A19: AII-018 | B19: 36 | C19: 30 - 39 | D19: Female | E19: Teacher | F19: Gbagyi | G19: Basic | H19: Community stakeholder | I19: Yes | J19: Field team invitation | K19: Did not attend | L19: Did not attend | M19: 0 | N19: Not assessed | O19: Not assessed | P19: Not assessed | Q19: Not assessed | R19: Not assessed | S19: No | T19: Not rated | U19: Concern about programme purpose | V19: School-based session | W19: Yes | X19: School-based session | Y19: Explain the purpose clearly to community leaders first.
A20: AII-019 | B20: 31 | C20: 30 - 39 | D20: Female | E20: Teacher | F20: English | G20: Fluent | H20: Adult woman | I20: Yes | J20: Field team invitation | K20: Attended | L20: 15 - 30 minutes late | M20: 3 | N20: Clear | O20: Women health, education and support services | P20: Moderate | Q20: Uncomfortable | R20: Listened quietly | S20: Yes | T20: 2 | U20: No major concern | V20: School-based session | W20: Yes | X20: School-based session | Y20: The team was respectful; repeat the session with local support.
A21: AII-020 | B21: 30 | C21: 30 - 39 | D21: Female | E21: Teacher | F21: Adara | G21: Conversational | H21: Adult woman | I21: Yes | J21: Friend/neighbour | K21: Did not attend | L21: Did not attend | M21: 0 | N21: Not assessed | O21: Not assessed | P21: Not assessed | Q21: Not assessed | R21: Not assessed | S21: No | T21: Not rated | U21: Language barrier | V21: Home/compound visit | W21: No | X21: Home/compound visit | Y21: Use a trusted local-language interpreter.
A22: AII-021 | B22: 13 | C22: 13 - 19 | D22: Female | E22: Community member | F22: Adara | G22: None | H22: Girl | I22: Yes | J22: Friend/neighbour | K22: Attended | L22: 15 - 30 minutes late | M22: 3 | N22: Limited | O22: Health talk only | P22: Very low | Q22: Uncomfortable | R22: Listened quietly | S22: Yes | T22: 2 | U22: No major concern | V22: Women group meeting | W22: Maybe | X22: Women group meeting | Y22: The team was respectful; repeat the session with local support.
A23: AII-022 | B23: 19 | C23: 13 - 19 | D23: Female | E23: Adolescent participant | F23: Adara | G23: Basic | H23: Young woman | I23: No | J23: Not applicable | K23: Did not attend | L23: Did not attend | M23: 0 | N23: Not assessed | O23: Not assessed | P23: Not assessed | Q23: Not assessed | R23: Not assessed | S23: No | T23: Not rated | U23: Did not hear about programme | V23: Women group meeting | W23: Maybe | X23: Women group meeting | Y23: Use community announcements and local networks earlier.
A24: AII-023 | B24: 56 | C24: 50+ | D24: Female | E24: Community member | F24: English | G24: Basic | H24: Adult woman | I24: Yes | J24: Teacher/school contact | K24: Attended | L24: 15 - 30 minutes late | M24: 5 | N24: Partial | O24: Women health and education | P24: Moderate | Q24: Neutral | R24: Contributed to discussion | S24: Yes | T24: 4 | U24: Need for elder engagement | V24: Local-language community meeting | W24: No | X24: Local-language community meeting | Y24: Meet village elders and gatekeepers before inviting participants.
A25: AII-024 | B25: 41 | C25: 40 - 49 | D25: Female | E25: Community member | F25: English | G25: Basic | H25: Adult woman | I25: Yes | J25: Teacher/school contact | K25: Did not attend | L25: Did not attend | M25: 0 | N25: Not assessed | O25: Not assessed | P25: Not assessed | Q25: Not assessed | R25: Not assessed | S25: No | T25: Not rated | U25: Language barrier | V25: School-based session | W25: Maybe | X25: School-based session | Y25: Use a trusted local-language interpreter.
A26: AII-025 | B26: 28 | C26: 20 - 29 | D26: Female | E26: Community member | F26: Adara | G26: None | H26: Young woman | I26: Yes | J26: Women group representative | K26: Did not attend | L26: Did not attend | M26: 0 | N26: Not assessed | O26: Not assessed | P26: Not assessed | Q26: Not assessed | R26: Not assessed | S26: No | T26: Not rated | U26: Household/time constraints | V26: Radio announcement | W26: Yes | X26: Radio announcement | Y26: Choose a time that does not conflict with household responsibilities.
A27: AII-026 | B27: 18 | C27: 13 - 19 | D27: Female | E27: Adolescent participant | F27: Adara | G27: None | H27: Young woman | I27: Yes | J27: Village/community leader | K27: Did not attend | L27: Did not attend | M27: 0 | N27: Not assessed | O27: Not assessed | P27: Not assessed | Q27: Not assessed | R27: Not assessed | S27: No | T27: Not rated | U27: Concern about programme purpose | V27: Women group meeting | W27: Maybe | X27: Women group meeting | Y27: Explain the purpose clearly to community leaders first.
A28: AII-027 | B28: 14 | C28: 13 - 19 | D28: Female | E28: Community member | F28: Adara | G28: None | H28: Girl | I28: Yes | J28: Field team invitation | K28: Attended | L28: On time | M28: 1 | N28: Limited | O28: Unclear; possibly external influence | P28: Very low | Q28: Very uncomfortable | R28: Observed only | S28: Yes | T28: 1 | U28: Household/time constraints | V28: Women group meeting | W28: No | X28: Women group meeting | Y28: Hold the next meeting after household chores and give advance notice.
A29: AII-028 | B29: 29 | C29: 20 - 29 | D29: Female | E29: Community member | F29: Adara | G29: Basic | H29: Young woman | I29: Yes | J29: Friend/neighbour | K29: Attended | L29: On time | M29: 2 | N29: Partial | O29: Women health and education | P29: Low | Q29: Very uncomfortable | R29: Observed only | S29: Yes | T29: 1 | U29: No major concern | V29: Women group meeting | W29: No | X29: Women group meeting | Y29: The team was respectful; repeat the session with local support.
A30: AII-029 | B30: 15 | C30: 13 - 19 | D30: Female | E30: Adolescent participant | F30: Adara | G30: Conversational | H30: Girl | I30: Yes | J30: Village/community leader | K30: Attended | L30: 15 - 30 minutes late | M30: 5 | N30: Clear | O30: Women health, education and support services | P30: High | Q30: Comfortable | R30: Asked one question | S30: Yes | T30: 4 | U30: Need for clearer purpose explanation | V30: Women group meeting | W30: Yes | X30: Women group meeting | Y30: State clearly that the outreach is for health, education and referral information.
A31: AII-030 | B31: 15 | C31: 13 - 19 | D31: Female | E31: Adolescent participant | F31: Adara | G31: None | H31: Girl | I31: Yes | J31: Family member | K31: Attended | L31: 15 - 30 minutes late | M31: 2 | N31: Partial | O31: Unclear; possibly external influence | P31: Low | Q31: Neutral | R31: Listened quietly | S31: Yes | T31: 2 | U31: Need for clearer purpose explanation | V31: Women group meeting | W31: Maybe | X31: Women group meeting | Y31: State clearly that the outreach is for health, education and referral information.
A32: AII-031 | B32: 36 | C32: 30 - 39 | D32: Female | E32: Community member | F32: Adara | G32: None | H32: Adult woman | I32: Yes | J32: Friend/neighbour | K32: Did not attend | L32: Did not attend | M32: 0 | N32: Not assessed | O32: Not assessed | P32: Not assessed | Q32: Not assessed | R32: Not assessed | S32: No | T32: Not rated | U32: Concern about programme purpose | V32: Home/compound visit | W32: Yes | X32: Home/compound visit | Y32: Explain the purpose clearly to community leaders first.
A33: AII-032 | B33: 14 | C33: 13 - 19 | D33: Female | E33: Community member | F33: Adara | G33: None | H33: Girl | I33: Yes | J33: Friend/neighbour | K33: Attended | L33: On time | M33: 3 | N33: Limited | O33: Unclear; possibly external influence | P33: Very low | Q33: Very uncomfortable | R33: Listened quietly | S33: Yes | T33: 2 | U33: Need for elder engagement | V33: Local-language community meeting | W33: No | X33: Local-language community meeting | Y33: Meet village elders and gatekeepers before inviting participants.
A34: AII-033 | B34: 14 | C34: 13 - 19 | D34: Female | E34: Adolescent participant | F34: Hausa | G34: None | H34: Girl | I34: Yes | J34: Religious/community announcement | K34: Attended | L34: On time | M34: 2 | N34: Limited | O34: Unsure why women and girls were invited | P34: Very low | Q34: Very uncomfortable | R34: Observed only | S34: Yes | T34: 2 | U34: Need for clearer purpose explanation | V34: School-based session | W34: No | X34: School-based session | Y34: State clearly that the outreach is for health, education and referral information.
A35: AII-034 | B35: 46 | C35: 40 - 49 | D35: Female | E35: Parent/guardian | F35: Gbagyi | G35: None | H35: Adult woman | I35: Yes | J35: Women group representative | K35: Attended | L35: 15 - 30 minutes late | M35: 4 | N35: Partial | O35: Unclear; possibly external influence | P35: Moderate | Q35: Neutral | R35: Contributed to discussion | S35: No | T35: 3 | U35: Need for clearer purpose explanation | V35: Women group meeting | W35: No | X35: Women group meeting | Y35: No feedback recorded.
A36: AII-035 | B36: 39 | C36: 30 - 39 | D36: Female | E36: Community member | F36: Adara | G36: Basic | H36: Adult woman | I36: Yes | J36: Women group representative | K36: Attended | L36: 15 - 30 minutes late | M36: 2 | N36: Partial | O36: Women health and education | P36: Moderate | Q36: Neutral | R36: Listened quietly | S36: Yes | T36: 3 | U36: Household/time constraints | V36: Women group meeting | W36: No | X36: Women group meeting | Y36: Hold the next meeting after household chores and give advance notice.
A37: AII-036 | B37: 41 | C37: 40 - 49 | D37: Female | E37: Teacher | F37: Gbagyi | G37: Basic | H37: Adult woman | I37: No | J37: Not applicable | K37: Did not attend | L37: Did not attend | M37: 0 | N37: Not assessed | O37: Not assessed | P37: Not assessed | Q37: Not assessed | R37: Not assessed | S37: No | T37: Not rated | U37: Did not hear about programme | V37: School-based session | W37: No | X37: School-based session | Y37: Use community announcements and local networks earlier.
A38: AII-037 | B38: 61 | C38: 50+ | D38: Female | E38: Village/community leader | F38: Hausa | G38: Basic | H38: Adult woman | I38: Yes | J38: Religious/community announcement | K38: Did not attend | L38: Did not attend | M38: 0 | N38: Not assessed | O38: Not assessed | P38: Not assessed | Q38: Not assessed | R38: Not assessed | S38: No | T38: Not rated | U38: Insufficient prior information | V38: Women group meeting | W38: Maybe | X38: Women group meeting | Y38: Share information through elders and women leaders before the event.
A39: AII-038 | B39: 20 | C39: 20 - 29 | D39: Female | E39: Community member | F39: Adara | G39: Basic | H39: Young woman | I39: Yes | J39: Friend/neighbour | K39: Attended | L39: 15 - 30 minutes late | M39: 2 | N39: Partial | O39: Unclear; possibly external influence | P39: Low | Q39: Uncomfortable | R39: Observed only | S39: No | T39: 3 | U39: Language barrier | V39: Women group meeting | W39: No | X39: Women group meeting | Y39: No feedback recorded.
A40: AII-039 | B40: 15 | C40: 13 - 19 | D40: Female | E40: Adolescent participant | F40: Adara | G40: None | H40: Girl | I40: Yes | J40: Family member | K40: Attended | L40: On time | M40: 3 | N40: Limited | O40: Health talk only | P40: Very low | Q40: Very uncomfortable | R40: Listened quietly | S40: Yes | T40: 2 | U40: No major concern | V40: School-based session | W40: No | X40: School-based session | Y40: The team was respectful; repeat the session with local support.
...

Sheet Analysis
A1: Which age groups did the outreach actually reach?
A2: Attendance by Age group | B2: Attendance_Status
A3: Age_Group | C3: Attended | D3: Did not attend | E3: Grand Total | G3: Did language ability affect how well participants understood the programme?
B4: 0 | E4: 0 | G4: Attendance by Age group | H4: Programme_Understanding
A5: 13 - 19 | C5: 49 | D5: 23 | E5: 72 | G5: English_Proficiency | I5: Clear | J5: Limited | K5: Not assessed | L5: Partial | M5: Grand Total
A6: 20 - 29 | C6: 15 | D6: 7 | E6: 22 | H6: 0 | M6: 0
A7: 30 - 39 | C7: 21 | D7: 13 | E7: 34 | G7: Basic | I7: 8 | J7: 5 | K7: 18 | L7: 32 | M7: 63
A8: 40 - 49 | C8: 25 | D8: 13 | E8: 38 | G8: Conversational | I8: 16 | K8: 15 | L8: 6 | M8: 37
A9: 50+ | C9: 20 | D9: 14 | E9: 34 | G9: Fluent | I9: 13 | K9: 5 | L9: 1 | M9: 19
A10: Grand Total | B10: 0 | C10: 130 | D10: 70 | E10: 200 | G10: None | J10: 25 | K10: 32 | L10: 24 | M10: 81
G11: Grand Total | H11: 0 | I11: 37 | J11: 30 | K11: 70 | L11: 63 | M11: 200
A13: Which participant groups did the outreach successfully reach, and which groups were missed?
A14: Participation Groups | B14: Attendance_Status
A15: Participant_Type | C15: Attended | D15: Did not attend | E15: Grand Total | G15: Is there a relationship between understanding the programme and trusting the organisation?
B16: 0 | E16: 0 | G16: Attendance by Age group | H16: Trust_Level
A17: Adult woman | C17: 59 | D17: 37 | E17: 96 | G17: Programme_Understanding | I17: High | J17: Low | K17: Moderate | L17: Not assessed | M17: Very high | N17: Very low | O17: Grand Total
A18: Community stakeholder | C18: 7 | D18: 3 | E18: 10 | H18: 0 | O18: 0
A19: Girl | C19: 37 | D19: 15 | E19: 52 | G19: Clear | I19: 12 | J19: 6 | K19: 13 | M19: 6 | O19: 37
A20: Young woman | C20: 27 | D20: 15 | E20: 42 | G20: Limited | J20: 8 | M20: 2 | N20: 20 | O20: 30
A21: Grand Total | B21: 0 | C21: 130 | D21: 70 | E21: 200 | G21: Not assessed | L21: 70 | O21: 70
G22: Partial | I22: 5 | J22: 23 | K22: 28 | N22: 7 | O22: 63
G23: Grand Total | H23: 0 | I23: 17 | J23: 37 | K23: 41 | L23: 70 | M23: 8 | N23: 27 | O23: 200
A25: Did language ability affect how well participants understood the programme?
A26: Attendance by Age group | B26: Programme_Understanding | C26: Participation_Level
C27: Total | D27: Clear | I27: Clear Total | J27: Limited | M27: Limited Total | N27: Not assessed | O27: Not assessed Total | P27: Partial | T27: Partial Total | U27: Grand Total
A28: Trust_Level | D28: Actively engaged | E28: Asked one question | F28: Contributed to discussion | G28: Listened quietly | H28: Observed only | J28: Asked one question | K28: Listened quietly | L28: Observed only | N28: Not assessed | P28: Asked one question | Q28: Contributed to discussion | R28: Listened quietly | S28: Observed only
B29: 0 | C29: 0 | U29: 0
A30: High | D30: 3 | E30: 2 | F30: 7 | I30: 12 | P30: 3 | Q30: 2 | T30: 5 | U30: 17
A31: Low | E31: 3 | H31: 3 | I31: 6 | J31: 3 | K31: 1 | L31: 4 | M31: 8 | P31: 2 | R31: 11 | S31: 10 | T31: 23 | U31: 37
A32: Moderate | D32: 1 | E32: 4 | F32: 2 | G32: 4 | H32: 2 | I32: 13 | P32: 6 | Q32: 12 | R32: 8 | S32: 2 | T32: 28 | U32: 41
A33: Not assessed | N33: 70 | O33: 70 | U33: 70
A34: Very high | D34: 3 | E34: 1 | F34: 2 | I34: 6 | L34: 2 | M34: 2 | U34: 8
A35: Very low | J35: 1 | K35: 10 | L35: 9 | M35: 20 | P35: 1 | R35: 2 | S35: 4 | T35: 7 | U35: 27
A36: Grand Total | B36: 0 | C36: 0 | D36: 7 | E36: 10 | F36: 11 | G36: 4 | H36: 5 | I36: 37 | J36: 4 | K36: 11 | L36: 15 | M36: 30 | N36: 70 | O36: 70 | P36: 12 | Q36: 14 | R36: 21 | S36: 16 | T36: 63 | U36: 200
A41: Main Concerns
A42: Main_Concern | B42: Participation Groups
B43: 0
A44: Concern about programme purpose | B44: 10
A45: Did not hear about programme | B45: 32
A46: Household/time constraints | B46: 17
...

Sheet Dashboard
B1: Aderyn Impact Initiative · Kallah Outreach Performance Dashboard | AB1: CHART DATA — formulas on Clean Data; feeds the dashboard (do not delete)
B2: Why was engagement limited, and what must change before AII returns? Women & girls outreach, Kallah, Kajuru LGA, Kaduna State · n = 200 participants | AB2: Attendance by age group
AC3: Attended | AD3: Did not attend | AE3: Attendance rate
B4: PARTICIPANTS SURVEYED | F4: ATTENDANCE RATE | J4: CLEAR UNDERSTANDING | N4: HIGH / VERY HIGH TRUST | R4: AVG. SATISFACTION | V4: WOULD ATTEND FOLLOW-UP | AB4: 13 - 19 | AC4: =COUNTIFS('Clean Data'!$C$2:$C$1000,$AB4,'Clean Data'!$K$2:$K$1000,"Attended") -> 49 | AD4: =COUNTIFS('Clean Data'!$C$2:$C$1000,$AB4,'Clean Data'!$K$2:$K$1000,"Did not attend") -> 23 | AE4: =IFERROR(AC4/(AC4+AD4),0) -> 0.68055556
B5: =COUNTA('Clean Data'!$A$2:$A$1000) -> 200 | F5: =COUNTIFS('Clean Data'!$K$2:$K$1000,"Attended")/COUNTA('Clean Data'!$A$2:$A$1000) -> 0.65 | J5: =COUNTIFS('Clean Data'!$N$2:$N$1000,"Clear")/COUNTIFS('Clean Data'!$K$2:$K$1000,"Attended") -> 0.28461538 | N5: =(COUNTIFS('Clean Data'!$P$2:$P$1000,"High")+COUNTIFS('Clean Data'!$P$2:$P$1000,"Very high"))/COUNTIFS('Clean Data'!$K$2:$K$1000,"Attended") -> 0.19230769 | R5: =AVERAGE('Clean Data'!$T$2:$T$1000) -> 2.5230769 | V5: =COUNTIFS('Clean Data'!$W$2:$W$1000,"Yes")/COUNTA('Clean Data'!$A$2:$A$1000) -> 0.315 | AB5: 20 - 29 | AC5: =COUNTIFS('Clean Data'!$C$2:$C$1000,$AB5,'Clean Data'!$K$2:$K$1000,"Attended") -> 15 | AD5: =COUNTIFS('Clean Data'!$C$2:$C$1000,$AB5,'Clean Data'!$K$2:$K$1000,"Did not attend") -> 7 | AE5: =IFERROR(AC5/(AC5+AD5),0) -> 0.68181818
AB6: 30 - 39 | AC6: =COUNTIFS('Clean Data'!$C$2:$C$1000,$AB6,'Clean Data'!$K$2:$K$1000,"Attended") -> 21 | AD6: =COUNTIFS('Clean Data'!$C$2:$C$1000,$AB6,'Clean Data'!$K$2:$K$1000,"Did not attend") -> 13 | AE6: =IFERROR(AC6/(AC6+AD6),0) -> 0.61764706
B7: =COUNTIFS('Clean Data'!$I$2:$I$1000,"No")&" never heard of the outreach" -> 32 never heard of the outreach | F7: =COUNTIFS('Clean Data'!$K$2:$K$1000,"Attended")&" of "&COUNTA('Clean Data'!$A$2:$A$1000)&" attended" -> 130 of 200 attended | J7: =COUNTIFS('Clean Data'!$N$2:$N$1000,"Clear")&" of "&COUNTIFS('Clean Data'!$K$2:$K$1000,"Attended")&" attendees" -> 37 of 130 attendees | N7: =(COUNTIFS('Clean Data'!$P$2:$P$1000,"High")+COUNTIFS('Clean Data'!$P$2:$P$1000,"Very high"))&" of "&COUNTIFS('Clean Data'!$K$2:$K$1000,"Attended")&" attendees" -> 25 of 130 attendees | R7: ="out of 5 (attendees)" -> out of 5 (attendees) | V7: =COUNTIFS('Clean Data'!$W$2:$W$1000,"Yes")&" yes · "&COUNTIFS('Clean Data'!$W$2:$W$1000,"Maybe")&" maybe · "&COUNTIFS('Clean Data'!$W$2:$W$1000,"No")&" no" -> 63 yes · 62 maybe · 75 no | AB7: 40 - 49 | AC7: =COUNTIFS('Clean Data'!$C$2:$C$1000,$AB7,'Clean Data'!$K$2:$K$1000,"Attended") -> 25 | AD7: =COUNTIFS('Clean Data'!$C$2:$C$1000,$AB7,'Clean Data'!$K$2:$K$1000,"Did not attend") -> 13 | AE7: =IFERROR(AC7/(AC7+AD7),0) -> 0.65789474
AB8: 50+ | AC8: =COUNTIFS('Clean Data'!$C$2:$C$1000,$AB8,'Clean Data'!$K$2:$K$1000,"Attended") -> 20 | AD8: =COUNTIFS('Clean Data'!$C$2:$C$1000,$AB8,'Clean Data'!$K$2:$K$1000,"Did not attend") -> 14 | AE8: =IFERROR(AC8/(AC8+AD8),0) -> 0.58823529
B9: 1 · REACH — Who did the outreach actually reach, and who was missed?
B10: Attendance by age group | N10: Attendance by participant group | AB10: Attendance by participant type
B11: ="Highest attendance: "&INDEX($AB$4:$AB$8,MATCH(MAX($AE$4:$AE$8),$AE$4:$AE$8,0))&" ("&TEXT(MAX($AE$4:$AE$8),"0%")&"); lowest: "&INDEX($AB$4:$AB$8,MATCH(MIN($AE$4:$AE$8),$AE$4:$AE$8,0))&" ("&TEXT(MIN($AE$4:$AE$8),"0%")&")" -> Highest attendance: 20 - 29 (68%); lowest: 50+ (59%) | N11: ="Highest attendance: "&INDEX($AB$12:$AB$15,MATCH(MAX($AE$12:$AE$15),$AE$12:$AE$15,0))&" ("&TEXT(MAX($AE$12:$AE$15),"0%")&"); lowest: "&INDEX($AB$12:$AB$15,MATCH(MIN($AE$12:$AE$15),$AE$12:$AE$15,0))&" ("&TEXT(MIN($AE$12:$AE$15),"0%")&")" -> Highest attendance: Girl (71%); lowest: Adult woman (61%) | AC11: Attended | AD11: Did not attend | AE11: Attendance rate
AB12: Adult woman | AC12: =COUNTIFS('Clean Data'!$H$2:$H$1000,$AB12,'Clean Data'!$K$2:$K$1000,"Attended") -> 59 | AD12: =COUNTIFS('Clean Data'!$H$2:$H$1000,$AB12,'Clean Data'!$K$2:$K$1000,"Did not attend") -> 37 | AE12: =IFERROR(AC12/(AC12+AD12),0) -> 0.61458333
AB13: Young woman | AC13: =COUNTIFS('Clean Data'!$H$2:$H$1000,$AB13,'Clean Data'!$K$2:$K$1000,"Attended") -> 27 | AD13: =COUNTIFS('Clean Data'!$H$2:$H$1000,$AB13,'Clean Data'!$K$2:$K$1000,"Did not attend") -> 15 | AE13: =IFERROR(AC13/(AC13+AD13),0) -> 0.64285714
AB14: Girl | AC14: =COUNTIFS('Clean Data'!$H$2:$H$1000,$AB14,'Clean Data'!$K$2:$K$1000,"Attended") -> 37 | AD14: =COUNTIFS('Clean Data'!$H$2:$H$1000,$AB14,'Clean Data'!$K$2:$K$1000,"Did not attend") -> 15 | AE14: =IFERROR(AC14/(AC14+AD14),0) -> 0.71153846
AB15: Community stakeholder | AC15: =COUNTIFS('Clean Data'!$H$2:$H$1000,$AB15,'Clean Data'!$K$2:$K$1000,"Attended") -> 7 | AD15: =COUNTIFS('Clean Data'!$H$2:$H$1000,$AB15,'Clean Data'!$K$2:$K$1000,"Did not attend") -> 3 | AE15: =IFERROR(AC15/(AC15+AD15),0) -> 0.7
AB17: Understanding by English proficiency (attendees)
AC18: Clear | AD18: Partial | AE18: Limited | AF18: Attendees | AG18: % clear
AB19: None | AC19: =COUNTIFS('Clean Data'!$G$2:$G$1000,$AB19,'Clean Data'!$N$2:$N$1000,"Clear") -> 0 | AD19: =COUNTIFS('Clean Data'!$G$2:$G$1000,$AB19,'Clean Data'!$N$2:$N$1000,"Partial") -> 24 | AE19: =COUNTIFS('Clean Data'!$G$2:$G$1000,$AB19,'Clean Data'!$N$2:$N$1000,"Limited") -> 25 | AF19: =SUM(AC19:AE19) -> 49 | AG19: =IFERROR(AC19/AF19,0) -> 0
AB20: Basic | AC20: =COUNTIFS('Clean Data'!$G$2:$G$1000,$AB20,'Clean Data'!$N$2:$N$1000,"Clear") -> 8 | AD20: =COUNTIFS('Clean Data'!$G$2:$G$1000,$AB20,'Clean Data'!$N$2:$N$1000,"Partial") -> 32 | AE20: =COUNTIFS('Clean Data'!$G$2:$G$1000,$AB20,'Clean Data'!$N$2:$N$1000,"Limited") -> 5 | AF20: =SUM(AC20:AE20) -> 45 | AG20: =IFERROR(AC20/AF20,0) -> 0.17777778
AB21: Conversational | AC21: =COUNTIFS('Clean Data'!$G$2:$G$1000,$AB21,'Clean Data'!$N$2:$N$1000,"Clear") -> 16 | AD21: =COUNTIFS('Clean Data'!$G$2:$G$1000,$AB21,'Clean Data'!$N$2:$N$1000,"Partial") -> 6 | AE21: =COUNTIFS('Clean Data'!$G$2:$G$1000,$AB21,'Clean Data'!$N$2:$N$1000,"Limited") -> 0 | AF21: =SUM(AC21:AE21) -> 22 | AG21: =IFERROR(AC21/AF21,0) -> 0.72727273
AB22: Fluent | AC22: =COUNTIFS('Clean Data'!$G$2:$G$1000,$AB22,'Clean Data'!$N$2:$N$1000,"Clear") -> 13 | AD22: =COUNTIFS('Clean Data'!$G$2:$G$1000,$AB22,'Clean Data'!$N$2:$N$1000,"Partial") -> 1 | AE22: =COUNTIFS('Clean Data'!$G$2:$G$1000,$AB22,'Clean Data'!$N$2:$N$1000,"Limited") -> 0 | AF22: =SUM(AC22:AE22) -> 14 | AG22: =IFERROR(AC22/AF22,0) -> 0.92857143
AB24: Perceived purpose of the outreach (attendees)
AC25: Attendees | AD25: % of attendees
B26: 2 · LANGUAGE & CLARITY — Did language ability affect how well the programme was understood? | AB26: Women’s health, education & support services | AC26: =COUNTIFS('Clean Data'!$O$2:$O$1000,"Women*health, education and support*",'Clean Data'!$K$2:$K$1000,"Attended") -> 37 | AD26: =IFERROR(AC26/COUNTIFS('Clean Data'!$K$2:$K$1000,"Attended"),0) -> 0.28461538
B27: Programme understanding by English proficiency (attendees) | N27: What did attendees think the outreach was for? | AB27: Women’s health and education | AC27: =COUNTIFS('Clean Data'!$O$2:$O$1000,"Women*health and education",'Clean Data'!$K$2:$K$1000,"Attended") -> 37 | AD27: =IFERROR(AC27/COUNTIFS('Clean Data'!$K$2:$K$1000,"Attended"),0) -> 0.28461538
B28: ="Clear understanding: "&TEXT($AG$19,"0%")&" of those with no English vs "&TEXT($AG$22,"0%")&" of fluent speakers" -> Clear understanding: 0% of those with no English vs 93% of fluent speakers | N28: ="Only "&TEXT($AD$26,"0%")&" named the purpose fully; "&TEXT($AD$30,"0%")&" suspected outside influence and "&TEXT($AD$29,"0%")&" were unsure why they were invited" -> Only 28% named the purpose fully; 28% suspected outside influence and 12% were unsure why they were invited | AB28: Health talk only | AC28: =COUNTIFS('Clean Data'!$O$2:$O$1000,"Health talk only",'Clean Data'!$K$2:$K$1000,"Attended") -> 3 | AD28: =IFERROR(AC28/COUNTIFS('Clean Data'!$K$2:$K$1000,"Attended"),0) -> 0.023076923
AB29: Unsure why women/girls were invited | AC29: =COUNTIFS('Clean Data'!$O$2:$O$1000,"Unsure why*",'Clean Data'!$K$2:$K$1000,"Attended") -> 16 | AD29: =IFERROR(AC29/COUNTIFS('Clean Data'!$K$2:$K$1000,"Attended"),0) -> 0.12307692
AB30: Unclear; possibly external influence | AC30: =COUNTIFS('Clean Data'!$O$2:$O$1000,"Unclear; possibly external*",'Clean Data'!$K$2:$K$1000,"Attended") -> 37 | AD30: =IFERROR(AC30/COUNTIFS('Clean Data'!$K$2:$K$1000,"Attended"),0) -> 0.28461538
AB32: Trust level by programme understanding (attendees)
AC33: Very high | AD33: High | AE33: Moderate | AF33: Low | AG33: Very low | AH33: Attendees | AI33: % high / very high
AB34: Clear | AC34: =COUNTIFS('Clean Data'!$N$2:$N$1000,$AB34,'Clean Data'!$P$2:$P$1000,"Very high") -> 6 | AD34: =COUNTIFS('Clean Data'!$N$2:$N$1000,$AB34,'Clean Data'!$P$2:$P$1000,"High") -> 12 | AE34: =COUNTIFS('Clean Data'!$N$2:$N$1000,$AB34,'Clean Data'!$P$2:$P$1000,"Moderate") -> 13 | AF34: =COUNTIFS('Clean Data'!$N$2:$N$1000,$AB34,'Clean Data'!$P$2:$P$1000,"Low") -> 6 | AG34: =COUNTIFS('Clean Data'!$N$2:$N$1000,$AB34,'Clean Data'!$P$2:$P$1000,"Very low") -> 0 | AH34: =SUM(AC34:AG34) -> 37 | AI34: =IFERROR((AC34+AD34)/AH34,0) -> 0.48648649
AB35: Partial | AC35: =COUNTIFS('Clean Data'!$N$2:$N$1000,$AB35,'Clean Data'!$P$2:$P$1000,"Very high") -> 0 | AD35: =COUNTIFS('Clean Data'!$N$2:$N$1000,$AB35,'Clean Data'!$P$2:$P$1000,"High") -> 5 | AE35: =COUNTIFS('Clean Data'!$N$2:$N$1000,$AB35,'Clean Data'!$P$2:$P$1000,"Moderate") -> 28 | AF35: =COUNTIFS('Clean Data'!$N$2:$N$1000,$AB35,'Clean Data'!$P$2:$P$1000,"Low") -> 23 | AG35: =COUNTIFS('Clean Data'!$N$2:$N$1000,$AB35,'Clean Data'!$P$2:$P$1000,"Very low") -> 7 | AH35: =SUM(AC35:AG35) -> 63 | AI35: =IFERROR((AC35+AD35)/AH35,0) -> 0.079365079
AB36: Limited | AC36: =COUNTIFS('Clean Data'!$N$2:$N$1000,$AB36,'Clean Data'!$P$2:$P$1000,"Very high") -> 2 | AD36: =COUNTIFS('Clean Data'!$N$2:$N$1000,$AB36,'Clean Data'!$P$2:$P$1000,"High") -> 0 | AE36: =COUNTIFS('Clean Data'!$N$2:$N$1000,$AB36,'Clean Data'!$P$2:$P$1000,"Moderate") -> 0 | AF36: =COUNTIFS('Clean Data'!$N$2:$N$1000,$AB36,'Clean Data'!$P$2:$P$1000,"Low") -> 8 | AG36: =COUNTIFS('Clean Data'!$N$2:$N$1000,$AB36,'Clean Data'!$P$2:$P$1000,"Very low") -> 20 | AH36: =SUM(AC36:AG36) -> 30 | AI36: =IFERROR((AC36+AD36)/AH36,0) -> 0.066666667
AB38: Participation by trust group (attendees)
AC39: Actively engaged / contributed | AD39: Asked one question | AE39: Listened quietly | AF39: Observed only | AG39: Attendees | AH39: % active
AB40: High / very high trust | AC40: =COUNTIFS('Clean Data'!$P$2:$P$1000,"High",'Clean Data'!$R$2:$R$1000,"Actively engaged")+COUNTIFS('Clean Data'!$P$2:$P$1000,"High",'Clean Data'!$R$2:$R$1000,"Contributed to discussion")+COUNTIFS('Clean Data'!$P$2:$P$1000,"Very high",'Clean Data'!$R$2:$R$1000,"Actively engaged")+COUNTIFS('Clean Data'!$P$2:$P$1000,"Very high",'Clean Data'!$R$2:$R$1000,"Contributed to discussion") -> 17 | AD40: =COUNTIFS('Clean Data'!$P$2:$P$1000,"High",'Clean Data'!$R$2:$R$1000,"Asked one question")+COUNTIFS('Clean Data'!$P$2:$P$1000,"Very high",'Clean Data'!$R$2:$R$1000,"Asked one question") -> 6 | AE40: =COUNTIFS('Clean Data'!$P$2:$P$1000,"High",'Clean Data'!$R$2:$R$1000,"Listened quietly")+COUNTIFS('Clean Data'!$P$2:$P$1000,"Very high",'Clean Data'!$R$2:$R$1000,"Listened quietly") -> 0 | AF40: =COUNTIFS('Clean Data'!$P$2:$P$1000,"High",'Clean Data'!$R$2:$R$1000,"Observed only")+COUNTIFS('Clean Data'!$P$2:$P$1000,"Very high",'Clean Data'!$R$2:$R$1000,"Observed only") -> 2 | AG40: =SUM(AC40:AF40) -> 25 | AH40: =IFERROR(AC40/AG40,0) -> 0.68
AB41: Moderate trust | AC41: =COUNTIFS('Clean Data'!$P$2:$P$1000,"Moderate",'Clean Data'!$R$2:$R$1000,"Actively engaged")+COUNTIFS('Clean Data'!$P$2:$P$1000,"Moderate",'Clean Data'!$R$2:$R$1000,"Contributed to discussion") -> 15 | AD41: =COUNTIFS('Clean Data'!$P$2:$P$1000,"Moderate",'Clean Data'!$R$2:$R$1000,"Asked one question") -> 10 | AE41: =COUNTIFS('Clean Data'!$P$2:$P$1000,"Moderate",'Clean Data'!$R$2:$R$1000,"Listened quietly") -> 12 | AF41: =COUNTIFS('Clean Data'!$P$2:$P$1000,"Moderate",'Clean Data'!$R$2:$R$1000,"Observed only") -> 4 | AG41: =SUM(AC41:AF41) -> 41 | AH41: =IFERROR(AC41/AG41,0) -> 0.36585366
AB42: Low / very low trust | AC42: =COUNTIFS('Clean Data'!$P$2:$P$1000,"Low",'Clean Data'!$R$2:$R$1000,"Actively engaged")+COUNTIFS('Clean Data'!$P$2:$P$1000,"Low",'Clean Data'!$R$2:$R$1000,"Contributed to discussion")+COUNTIFS('Clean Data'!$P$2:$P$1000,"Very low",'Clean Data'!$R$2:$R$1000,"Actively engaged")+COUNTIFS('Clean Data'!$P$2:$P$1000,"Very low",'Clean Data'!$R$2:$R$1000,"Contributed to discussion") -> 0 | AD42: =COUNTIFS('Clean Data'!$P$2:$P$1000,"Low",'Clean Data'!$R$2:$R$1000,"Asked one question")+COUNTIFS('Clean Data'!$P$2:$P$1000,"Very low",'Clean Data'!$R$2:$R$1000,"Asked one question") -> 10 | AE42: =COUNTIFS('Clean Data'!$P$2:$P$1000,"Low",'Clean Data'!$R$2:$R$1000,"Listened quietly")+COUNTIFS('Clean Data'!$P$2:$P$1000,"Very low",'Clean Data'!$R$2:$R$1000,"Listened quietly") -> 24 | AF42: =COUNTIFS('Clean Data'!$P$2:$P$1000,"Low",'Clean Data'!$R$2:$R$1000,"Observed only")+COUNTIFS('Clean Data'!$P$2:$P$1000,"Very low",'Clean Data'!$R$2:$R$1000,"Observed only") -> 30 | AG42: =SUM(AC42:AF42) -> 64 | AH42: =IFERROR(AC42/AG42,0) -> 0
B43: 3 · UNDERSTANDING → TRUST → PARTICIPATION — Did understanding the programme build trust and engagement?
B44: Trust level by programme understanding (attendees) | N44: Participation level by trust (attendees) | AB44: Main concern — attendees vs non-attendees
...

Sheet Recommendations
